
2025-03-28 12:00:52 - Successfully run
************************************************

2025-03-28 14:45:03 - Successfully run
************************************************

2025-03-29 14:45:03 - Successfully run
************************************************

2025-03-30 14:45:03 - Successfully run
************************************************

2025-03-31 14:09:26 - Successfully run
************************************************

2025-03-31 14:09:31 - Successfully run
************************************************

2025-03-31 14:09:43 - Error: list index out of range
Traceback (most recent call last):
  File "C:\xrt\src\proc\process_solar_scans.py", line 243, in main
    idx_file_morning = [ii for ii in range(len(list_fit)) if '08450' in list_fit[ii]][0]
                       ~~~~~~~~~~~~~~~~~~~~~~~~~~~~~~~~~~~~~~~~~~~~~~~~~~~~~~~~~~~~~~^^^
IndexError: list index out of range

************************************************

2025-03-31 14:09:48 - Successfully run
************************************************

2025-03-31 14:09:52 - Successfully run
************************************************

2025-03-31 14:09:57 - Successfully run
************************************************

2025-03-31 14:10:01 - Successfully run
************************************************

2025-03-31 14:10:36 - Successfully run
************************************************

2025-03-31 14:10:41 - Successfully run
************************************************

2025-03-31 14:10:46 - Successfully run
************************************************

2025-03-31 14:10:51 - Successfully run
************************************************

2025-03-31 14:10:57 - Successfully run
************************************************

2025-03-31 14:45:03 - Successfully run
************************************************

2025-04-01 14:45:03 - Successfully run
************************************************

2025-04-02 08:53:31 - Error: num must be an integer with 1 <= num <= 3, not 5
Traceback (most recent call last):
  File "C:\xrt\src\proc\process_solar_scans.py", line 636, in main
    ax_noon_after = fig.add_subplot(315)
                    ^^^^^^^^^^^^^^^^^^^^
  File "C:\Tools\python\venv\callisto_env\Lib\site-packages\matplotlib\figure.py", line 782, in add_subplot
    ax = projection_class(self, *args, **pkw)
         ^^^^^^^^^^^^^^^^^^^^^^^^^^^^^^^^^^^^
  File "C:\Tools\python\venv\callisto_env\Lib\site-packages\matplotlib\axes\_base.py", line 639, in __init__
    subplotspec = SubplotSpec._from_subplot_args(fig, args)
                  ^^^^^^^^^^^^^^^^^^^^^^^^^^^^^^^^^^^^^^^^^
  File "C:\Tools\python\venv\callisto_env\Lib\site-packages\matplotlib\gridspec.py", line 599, in _from_subplot_args
    raise ValueError(
ValueError: num must be an integer with 1 <= num <= 3, not 5

************************************************

2025-04-02 08:55:21 - Successfully run
************************************************

2025-04-02 08:57:44 - Successfully run
************************************************

2025-04-02 08:58:50 - Successfully run
************************************************

2025-04-02 09:00:28 - Successfully run
************************************************

2025-04-02 09:06:47 - Successfully run
************************************************

2025-04-02 09:07:24 - Successfully run
************************************************

2025-04-02 09:08:22 - Successfully run
************************************************

2025-04-02 09:54:22 - Successfully run
************************************************

2025-04-02 09:56:06 - Successfully run
************************************************

2025-04-02 09:57:02 - Successfully run
************************************************

2025-04-02 14:01:40 - Successfully run
************************************************

2025-04-02 14:06:33 - Successfully run
************************************************

2025-04-02 14:08:00 - Successfully run
************************************************

2025-04-02 14:09:33 - Successfully run
************************************************

2025-04-02 14:10:42 - Successfully run
************************************************

2025-04-02 14:11:32 - Successfully run
************************************************

2025-04-02 14:45:06 - Successfully run
************************************************

2025-04-03 09:19:12 - Error: 'utf-8' codec can't decode byte 0xb0 in position 110: invalid start byte
Traceback (most recent call last):
  File "C:\xrt\src\proc\process_solar_scans.py", line 182, in main
    df_motor = pd.read_csv(path_log_motor, sep=',', header=3)
               ^^^^^^^^^^^^^^^^^^^^^^^^^^^^^^^^^^^^^^^^^^^^^^
  File "C:\Tools\python\venv\callisto_env\Lib\site-packages\pandas\io\parsers\readers.py", line 1026, in read_csv
    return _read(filepath_or_buffer, kwds)
           ^^^^^^^^^^^^^^^^^^^^^^^^^^^^^^^
  File "C:\Tools\python\venv\callisto_env\Lib\site-packages\pandas\io\parsers\readers.py", line 620, in _read
    parser = TextFileReader(filepath_or_buffer, **kwds)
             ^^^^^^^^^^^^^^^^^^^^^^^^^^^^^^^^^^^^^^^^^^
  File "C:\Tools\python\venv\callisto_env\Lib\site-packages\pandas\io\parsers\readers.py", line 1620, in __init__
    self._engine = self._make_engine(f, self.engine)
                   ^^^^^^^^^^^^^^^^^^^^^^^^^^^^^^^^^
  File "C:\Tools\python\venv\callisto_env\Lib\site-packages\pandas\io\parsers\readers.py", line 1898, in _make_engine
    return mapping[engine](f, **self.options)
           ^^^^^^^^^^^^^^^^^^^^^^^^^^^^^^^^^^
  File "C:\Tools\python\venv\callisto_env\Lib\site-packages\pandas\io\parsers\c_parser_wrapper.py", line 93, in __init__
    self._reader = parsers.TextReader(src, **kwds)
                   ^^^^^^^^^^^^^^^^^^^^^^^^^^^^^^^
  File "parsers.pyx", line 574, in pandas._libs.parsers.TextReader.__cinit__
  File "parsers.pyx", line 663, in pandas._libs.parsers.TextReader._get_header
  File "parsers.pyx", line 874, in pandas._libs.parsers.TextReader._tokenize_rows
  File "parsers.pyx", line 891, in pandas._libs.parsers.TextReader._check_tokenize_status
  File "parsers.pyx", line 2053, in pandas._libs.parsers.raise_parser_error
  File "<frozen codecs>", line 322, in decode
UnicodeDecodeError: 'utf-8' codec can't decode byte 0xb0 in position 110: invalid start byte

************************************************

2025-04-03 14:45:06 - Successfully run
************************************************

2025-04-04 14:45:06 - Successfully run
************************************************

2025-04-05 14:45:05 - Successfully run
************************************************

2025-04-06 14:45:05 - Successfully run
************************************************

2025-04-07 14:45:05 - Successfully run
************************************************

2025-04-08 14:45:05 - Successfully run
************************************************

2025-04-09 14:45:06 - Successfully run
************************************************

2025-04-10 14:45:06 - Successfully run
************************************************

2025-04-11 14:45:05 - Successfully run
************************************************

2025-04-12 14:45:06 - Successfully run
************************************************

2025-04-13 14:45:05 - Successfully run
************************************************

2025-04-14 14:45:05 - Successfully run
************************************************

2025-04-15 14:45:05 - Successfully run
************************************************

2025-04-16 14:45:06 - Successfully run
************************************************

2025-04-17 14:45:05 - Successfully run
************************************************

2025-04-18 14:45:06 - Successfully run
************************************************

2025-04-19 14:45:05 - Successfully run
************************************************

2025-04-20 14:45:06 - Successfully run
************************************************

2025-04-21 14:45:06 - Successfully run
************************************************

2025-04-22 14:45:01 - Error: index 0 is out of bounds for axis 0 with size 0
Traceback (most recent call last):
  File "C:\xrt\src\proc\process_solar_scans.py", line 245, in main
    idx_start_scanning_morning_before = np.where(msg_morning_before == ' New scanning59 position')[0][0]
                                        ~~~~~~~~~~~~~~~~~~~~~~~~~~~~~~~~~~~~~~~~~~~~~~~~~~~~~~~~~~~~~^^^
IndexError: index 0 is out of bounds for axis 0 with size 0

************************************************

2025-04-23 14:45:05 - Successfully run
************************************************

2025-04-24 14:45:06 - Successfully run
************************************************

2025-04-25 14:45:05 - Successfully run
************************************************

2025-04-26 14:45:05 - Successfully run
************************************************

2025-04-27 14:45:05 - Successfully run
************************************************

2025-04-28 14:45:06 - Successfully run
************************************************

2025-04-29 14:45:05 - Successfully run
************************************************

2025-04-30 14:45:06 - Successfully run
************************************************

2025-05-01 14:45:06 - Successfully run
************************************************

2025-05-02 14:45:05 - Successfully run
************************************************

2025-05-03 14:45:05 - Successfully run
************************************************

2025-05-04 14:45:05 - Successfully run
************************************************

2025-05-05 14:45:05 - Successfully run
************************************************

2025-05-06 14:45:06 - Successfully run
************************************************

2025-05-07 14:45:06 - Successfully run
************************************************

2025-05-08 14:45:05 - Successfully run
************************************************

2025-05-09 14:45:05 - Successfully run
************************************************

2025-05-10 14:45:05 - Successfully run
************************************************

2025-05-11 14:45:05 - Successfully run
************************************************

2025-05-12 14:45:06 - Successfully run
************************************************

2025-05-13 11:18:31 - Error: index 0 is out of bounds for axis 0 with size 0
Traceback (most recent call last):
  File "C:\xrt\src\proc\process_solar_scans.py", line 245, in main
    idx_start_scanning_morning_before = np.where(msg_morning_before == ' New scanning59 position')[0][0]
                                        ~~~~~~~~~~~~~~~~~~~~~~~~~~~~~~~~~~~~~~~~~~~~~~~~~~~~~~~~~~~~~^^^
IndexError: index 0 is out of bounds for axis 0 with size 0

************************************************

2025-05-13 14:45:02 - Error: index 0 is out of bounds for axis 0 with size 0
Traceback (most recent call last):
  File "C:\xrt\src\proc\process_solar_scans.py", line 245, in main
    idx_start_scanning_morning_before = np.where(msg_morning_before == ' New scanning59 position')[0][0]
                                        ~~~~~~~~~~~~~~~~~~~~~~~~~~~~~~~~~~~~~~~~~~~~~~~~~~~~~~~~~~~~~^^^
IndexError: index 0 is out of bounds for axis 0 with size 0

************************************************

2025-05-13 16:04:09 - Found 6 scan in the motor log file for day 20250512
************************************************

2025-05-13 16:07:32 - Found 6 scan in the motor log file for day 20250512
************************************************

2025-05-13 16:10:21 - Found 7 scan in the motor log file for day 20250512
************************************************

2025-05-13 16:11:05 - Found 7 scan in the motor log file for day 20250512
************************************************

2025-05-13 16:11:44 - Found 7 scan in the motor log file for day 20250512
************************************************

2025-05-13 16:13:20 - Found 6 scan in the motor log file for day 20250512
************************************************

2025-05-13 16:13:35 - Found 6 scan in the motor log file for day 20250512
************************************************

2025-05-13 16:35:25 - Found 6 scan in the motor log file for day 20250512
************************************************

2025-05-13 19:32:08 - Found 5 scan in the motor log file for day 20250513
************************************************

2025-05-13 19:37:13 - Found 5 scan in the motor log file for day 20250513
************************************************

2025-05-13 19:38:58 - Found 5 scan in the motor log file for day 20250513
************************************************

2025-05-14 10:01:19 - Found 2 scan in the motor log file for day 20250514
************************************************

2025-05-14 10:34:32 - Found 5 scan in the motor log file for day 20250513
************************************************

2025-05-14 12:31:39 - The fit of the scan at 2025-05-14 10:59 has failed!
************************************************

2025-05-14 12:31:39 - Error is array must not contain infs or NaNs
************************************************

2025-05-14 12:32:26 - The fit of the scan at 2025-05-14 10:59 has failed!
************************************************

2025-05-14 12:32:26 - Error is array must not contain infs or NaNs
************************************************

2025-05-14 12:32:53 - Found 5 scan in the motor log file for day 20250513
************************************************

2025-05-14 12:32:53 - The fit of the scan at 2025-05-14 12:59 has failed!
************************************************

2025-05-14 12:32:53 - Error is array must not contain infs or NaNs
************************************************

2025-05-14 12:33:23 - Found 5 scan in the motor log file for day 20250513
************************************************

2025-05-14 12:33:55 - The fit of the scan at 2025-05-14 12:59 has failed!
************************************************

2025-05-14 12:33:55 - Error is array must not contain infs or NaNs
************************************************

2025-05-14 12:37:49 - Found 5 scan in the motor log file for day 20250513
************************************************

2025-05-14 12:38:38 - The fit of the scan at 2025-05-14 12:59 has failed!
************************************************

2025-05-14 12:38:38 - Error is array must not contain infs or NaNs
************************************************

2025-05-14 12:38:38 - The fit of the scan at 2025-05-14 13:59 has failed!
************************************************

2025-05-14 12:38:38 - Error is array must not contain infs or NaNs
************************************************

2025-05-14 12:40:36 - Found 5 scan in the motor log file for day 20250513
************************************************

2025-05-14 12:40:56 - Found 5 scan in the motor log file for day 20250513
************************************************

2025-05-14 12:43:43 - Found 5 scan in the motor log file for day 20250513
************************************************

2025-05-14 12:43:45 - Found 5 scan in the motor log file for day 20250513
************************************************

2025-05-14 12:43:47 - Found 5 scan in the motor log file for day 20250513
************************************************

2025-05-14 12:44:16 - Found 5 scan in the motor log file for day 20250513
************************************************

2025-05-14 12:55:38 - Found 5 scan in the motor log file for day 20250513
************************************************

2025-05-14 13:06:48 - Found 6 scan in the motor log file for day 20250512
************************************************

2025-05-14 14:45:07 - Successfully run
************************************************

2025-05-14 15:05:03 - Found 6 scan in the motor log file for day 20250512
************************************************

2025-05-14 15:41:43 - Successfully run
************************************************

2025-05-14 15:45:53 - Found 5 scan in the motor log file for day 20250513
************************************************

2025-05-14 15:46:14 - Found 6 scan in the motor log file for day 20250514
************************************************

2025-05-14 15:46:15 - Found 6 scan in the motor log file for day 20250514
************************************************

2025-05-15 14:45:08 - Successfully run
************************************************

2025-05-15 17:00:02 - Found 6 scan in the motor log file for day 20250514
************************************************

2025-05-15 17:04:05 - Found 6 scan in the motor log file for day 20250515
************************************************

2025-05-15 17:16:51 - Successfully run
************************************************

2025-05-15 17:16:52 - Successfully run
************************************************

2025-05-15 17:16:53 - Successfully run
************************************************

2025-05-15 17:16:55 - Successfully run
************************************************

2025-05-15 17:16:57 - Successfully run
************************************************

2025-05-15 17:17:00 - Successfully run
************************************************

2025-05-15 17:19:13 - Successfully run
************************************************

2025-05-15 17:19:13 - Successfully run
************************************************

2025-05-15 17:19:13 - Successfully run
************************************************

2025-05-15 17:19:13 - Successfully run
************************************************

2025-05-15 17:19:13 - Successfully run
************************************************

2025-05-15 17:19:13 - Successfully run
************************************************

2025-05-15 17:23:37 - Successfully run
************************************************

2025-05-15 17:23:37 - Successfully run
************************************************

2025-05-15 17:23:37 - Successfully run
************************************************

2025-05-15 17:23:37 - Successfully run
************************************************

2025-05-15 17:23:37 - Successfully run
************************************************

2025-05-15 17:23:37 - Successfully run
************************************************

2025-05-15 17:26:42 - Successfully run
************************************************

2025-05-15 17:26:42 - Successfully run
************************************************

2025-05-15 17:26:42 - Successfully run
************************************************

2025-05-15 17:26:42 - Successfully run
************************************************

2025-05-15 17:26:42 - Successfully run
************************************************

2025-05-15 17:26:42 - Successfully run
************************************************

2025-05-15 17:27:05 - Successfully run
************************************************

2025-05-15 17:27:05 - Successfully run
************************************************

2025-05-15 17:27:05 - Successfully run
************************************************

2025-05-15 17:27:05 - Successfully run
************************************************

2025-05-15 17:27:05 - Successfully run
************************************************

2025-05-15 17:27:05 - Successfully run
************************************************

2025-05-15 17:40:48 - Found 6 scan in the motor log file for day 20250515
************************************************

2025-05-15 17:40:48 - The fit of the scan at 2025-05-15 08:59 has failed!
************************************************

2025-05-15 17:40:48 - Error is array must not contain infs or NaNs
************************************************

2025-05-15 17:40:48 - Error: x and y must be the same size
Traceback (most recent call last):
  File "<ipython-input-3-5155b2ebb071>", line 187, in <module>
    ax1[i].scatter(dtimes_with_offset, data_avg, c='r', s=100, label='Morning (averaged)')
  File "c:\Tools\python\venv\callisto_env\Lib\site-packages\matplotlib\__init__.py", line 1478, in inner
    return func(ax, *map(sanitize_sequence, args), **kwargs)
           ^^^^^^^^^^^^^^^^^^^^^^^^^^^^^^^^^^^^^^^^^^^^^^^^^
  File "c:\Tools\python\venv\callisto_env\Lib\site-packages\matplotlib\axes\_axes.py", line 4655, in scatter
    raise ValueError("x and y must be the same size")
ValueError: x and y must be the same size

************************************************

2025-05-15 17:40:48 - The fit of the scan at 2025-05-15 09:59 has failed!
************************************************

2025-05-15 17:40:48 - Error is array must not contain infs or NaNs
************************************************

2025-05-15 17:40:48 - Error: x and y must be the same size
Traceback (most recent call last):
  File "<ipython-input-3-5155b2ebb071>", line 187, in <module>
    ax1[i].scatter(dtimes_with_offset, data_avg, c='r', s=100, label='Morning (averaged)')
  File "c:\Tools\python\venv\callisto_env\Lib\site-packages\matplotlib\__init__.py", line 1478, in inner
    return func(ax, *map(sanitize_sequence, args), **kwargs)
           ^^^^^^^^^^^^^^^^^^^^^^^^^^^^^^^^^^^^^^^^^^^^^^^^^
  File "c:\Tools\python\venv\callisto_env\Lib\site-packages\matplotlib\axes\_axes.py", line 4655, in scatter
    raise ValueError("x and y must be the same size")
ValueError: x and y must be the same size

************************************************

2025-05-15 17:40:49 - The fit of the scan at 2025-05-15 10:59 has failed!
************************************************

2025-05-15 17:40:49 - Error is array must not contain infs or NaNs
************************************************

2025-05-15 17:40:49 - Error: x and y must be the same size
Traceback (most recent call last):
  File "<ipython-input-3-5155b2ebb071>", line 187, in <module>
    ax1[i].scatter(dtimes_with_offset, data_avg, c='r', s=100, label='Morning (averaged)')
  File "c:\Tools\python\venv\callisto_env\Lib\site-packages\matplotlib\__init__.py", line 1478, in inner
    return func(ax, *map(sanitize_sequence, args), **kwargs)
           ^^^^^^^^^^^^^^^^^^^^^^^^^^^^^^^^^^^^^^^^^^^^^^^^^
  File "c:\Tools\python\venv\callisto_env\Lib\site-packages\matplotlib\axes\_axes.py", line 4655, in scatter
    raise ValueError("x and y must be the same size")
ValueError: x and y must be the same size

************************************************

2025-05-15 17:40:49 - The fit of the scan at 2025-05-15 11:59 has failed!
************************************************

2025-05-15 17:40:49 - Error is array must not contain infs or NaNs
************************************************

2025-05-15 17:40:49 - Error: x and y must be the same size
Traceback (most recent call last):
  File "<ipython-input-3-5155b2ebb071>", line 187, in <module>
    ax1[i].scatter(dtimes_with_offset, data_avg, c='r', s=100, label='Morning (averaged)')
  File "c:\Tools\python\venv\callisto_env\Lib\site-packages\matplotlib\__init__.py", line 1478, in inner
    return func(ax, *map(sanitize_sequence, args), **kwargs)
           ^^^^^^^^^^^^^^^^^^^^^^^^^^^^^^^^^^^^^^^^^^^^^^^^^
  File "c:\Tools\python\venv\callisto_env\Lib\site-packages\matplotlib\axes\_axes.py", line 4655, in scatter
    raise ValueError("x and y must be the same size")
ValueError: x and y must be the same size

************************************************

2025-05-15 17:40:49 - The fit of the scan at 2025-05-15 12:59 has failed!
************************************************

2025-05-15 17:40:49 - Error is array must not contain infs or NaNs
************************************************

2025-05-15 17:40:49 - Error: x and y must be the same size
Traceback (most recent call last):
  File "<ipython-input-3-5155b2ebb071>", line 187, in <module>
    ax1[i].scatter(dtimes_with_offset, data_avg, c='r', s=100, label='Morning (averaged)')
  File "c:\Tools\python\venv\callisto_env\Lib\site-packages\matplotlib\__init__.py", line 1478, in inner
    return func(ax, *map(sanitize_sequence, args), **kwargs)
           ^^^^^^^^^^^^^^^^^^^^^^^^^^^^^^^^^^^^^^^^^^^^^^^^^
  File "c:\Tools\python\venv\callisto_env\Lib\site-packages\matplotlib\axes\_axes.py", line 4655, in scatter
    raise ValueError("x and y must be the same size")
ValueError: x and y must be the same size

************************************************

2025-05-15 17:40:49 - The fit of the scan at 2025-05-15 13:59 has failed!
************************************************

2025-05-15 17:40:49 - Error is array must not contain infs or NaNs
************************************************

2025-05-15 17:40:49 - Error: x and y must be the same size
Traceback (most recent call last):
  File "<ipython-input-3-5155b2ebb071>", line 187, in <module>
    ax1[i].scatter(dtimes_with_offset, data_avg, c='r', s=100, label='Morning (averaged)')
  File "c:\Tools\python\venv\callisto_env\Lib\site-packages\matplotlib\__init__.py", line 1478, in inner
    return func(ax, *map(sanitize_sequence, args), **kwargs)
           ^^^^^^^^^^^^^^^^^^^^^^^^^^^^^^^^^^^^^^^^^^^^^^^^^
  File "c:\Tools\python\venv\callisto_env\Lib\site-packages\matplotlib\axes\_axes.py", line 4655, in scatter
    raise ValueError("x and y must be the same size")
ValueError: x and y must be the same size

************************************************

2025-05-15 17:41:28 - Found 6 scan in the motor log file for day 20250515
************************************************

2025-05-15 17:41:28 - Error: unsupported operand type(s) for -: 'int' and 'Timedelta'
Traceback (most recent call last):
  File "<ipython-input-1-5155b2ebb071>", line 128, in <module>
    data_avg = average_around_time(fit_data["datetimes"],
               ^^^^^^^^^^^^^^^^^^^^^^^^^^^^^^^^^^^^^^^^^^
  File "c:\wod_tests\utils.py", line 144, in average_around_time
    averages = [average_around(i) for i in range(len(df))]
                ^^^^^^^^^^^^^^^^^
  File "c:\wod_tests\utils.py", line 140, in average_around
    window = df.loc[date - delta : date + delta]
                    ~~~~~^~~~~~~
TypeError: unsupported operand type(s) for -: 'int' and 'Timedelta'

************************************************

2025-05-15 17:41:28 - Error: unsupported operand type(s) for -: 'int' and 'Timedelta'
Traceback (most recent call last):
  File "<ipython-input-1-5155b2ebb071>", line 128, in <module>
    data_avg = average_around_time(fit_data["datetimes"],
               ^^^^^^^^^^^^^^^^^^^^^^^^^^^^^^^^^^^^^^^^^^
  File "c:\wod_tests\utils.py", line 144, in average_around_time
    averages = [average_around(i) for i in range(len(df))]
                ^^^^^^^^^^^^^^^^^
  File "c:\wod_tests\utils.py", line 140, in average_around
    window = df.loc[date - delta : date + delta]
                    ~~~~~^~~~~~~
TypeError: unsupported operand type(s) for -: 'int' and 'Timedelta'

************************************************

2025-05-15 17:41:28 - Error: unsupported operand type(s) for -: 'int' and 'Timedelta'
Traceback (most recent call last):
  File "<ipython-input-1-5155b2ebb071>", line 128, in <module>
    data_avg = average_around_time(fit_data["datetimes"],
               ^^^^^^^^^^^^^^^^^^^^^^^^^^^^^^^^^^^^^^^^^^
  File "c:\wod_tests\utils.py", line 144, in average_around_time
    averages = [average_around(i) for i in range(len(df))]
                ^^^^^^^^^^^^^^^^^
  File "c:\wod_tests\utils.py", line 140, in average_around
    window = df.loc[date - delta : date + delta]
                    ~~~~~^~~~~~~
TypeError: unsupported operand type(s) for -: 'int' and 'Timedelta'

************************************************

2025-05-15 17:41:28 - Error: unsupported operand type(s) for -: 'int' and 'Timedelta'
Traceback (most recent call last):
  File "<ipython-input-1-5155b2ebb071>", line 128, in <module>
    data_avg = average_around_time(fit_data["datetimes"],
               ^^^^^^^^^^^^^^^^^^^^^^^^^^^^^^^^^^^^^^^^^^
  File "c:\wod_tests\utils.py", line 144, in average_around_time
    averages = [average_around(i) for i in range(len(df))]
                ^^^^^^^^^^^^^^^^^
  File "c:\wod_tests\utils.py", line 140, in average_around
    window = df.loc[date - delta : date + delta]
                    ~~~~~^~~~~~~
TypeError: unsupported operand type(s) for -: 'int' and 'Timedelta'

************************************************

2025-05-15 17:41:28 - Error: unsupported operand type(s) for -: 'int' and 'Timedelta'
Traceback (most recent call last):
  File "<ipython-input-1-5155b2ebb071>", line 128, in <module>
    data_avg = average_around_time(fit_data["datetimes"],
               ^^^^^^^^^^^^^^^^^^^^^^^^^^^^^^^^^^^^^^^^^^
  File "c:\wod_tests\utils.py", line 144, in average_around_time
    averages = [average_around(i) for i in range(len(df))]
                ^^^^^^^^^^^^^^^^^
  File "c:\wod_tests\utils.py", line 140, in average_around
    window = df.loc[date - delta : date + delta]
                    ~~~~~^~~~~~~
TypeError: unsupported operand type(s) for -: 'int' and 'Timedelta'

************************************************

2025-05-15 17:41:28 - Error: unsupported operand type(s) for -: 'int' and 'Timedelta'
Traceback (most recent call last):
  File "<ipython-input-1-5155b2ebb071>", line 128, in <module>
    data_avg = average_around_time(fit_data["datetimes"],
               ^^^^^^^^^^^^^^^^^^^^^^^^^^^^^^^^^^^^^^^^^^
  File "c:\wod_tests\utils.py", line 144, in average_around_time
    averages = [average_around(i) for i in range(len(df))]
                ^^^^^^^^^^^^^^^^^
  File "c:\wod_tests\utils.py", line 140, in average_around
    window = df.loc[date - delta : date + delta]
                    ~~~~~^~~~~~~
TypeError: unsupported operand type(s) for -: 'int' and 'Timedelta'

************************************************

2025-05-15 17:42:23 - Found 6 scan in the motor log file for day 20250515
************************************************

2025-05-15 17:42:23 - Successfully run
************************************************

2025-05-15 17:42:23 - Successfully run
************************************************

2025-05-15 17:42:23 - Successfully run
************************************************

2025-05-15 17:42:23 - Successfully run
************************************************

2025-05-15 17:42:24 - Successfully run
************************************************

2025-05-15 17:42:24 - Successfully run
************************************************
